Workbook

Sheet Kalkulation
A1: KTV Hockeycamp – Budgetübersicht
A2: Camp 1 & Camp 2 · Plan- und Ist-Zahlen · Beträge in EUR
A4: AUSGABEN
A5: Position | B5: Camp 1 geplant | C5: Camp 1 real | D5: Camp 2 geplant | E5: Camp 2 real | G5: Gesamt geplant | H5: Gesamt real | I5: Anmerkung
A6: Mannschaftszelte | B6: 84 | D6: 84 | G6: =B6+D6 -> 168 | H6: =C6+E6 -> 0 | I6: 3 Zelte für 2 Wochen
A7: Trainer | B7: 4200 | D7: 1500 | G7: =B7+D7 -> 5700 | H7: =C7+E7 -> 0
A8: Fahrtkosten-Zuschuss | D8: 250 | G8: =B8+D8 -> 250 | H8: =C8+E8 -> 0
A9: Catering | B9: =(B47+D47+10)*5*B53 -> 2583 | D9: =(B48+D48+10)*3*B53 -> 723.24 | G9: =B9+D9 -> 3306.24 | H9: =C9+E9 -> 0 | I9: 10 Portionen mehr bestellen
A10: T-Shirts | B10: 1300 | D10: 600 | G10: =B10+D10 -> 1900 | H10: =C10+E10 -> 0
A11: Obstpausen | B11: =(B47+D47)*5*B54 -> 475 | D11: =(B48+D48)*3*B54 -> 117 | G11: =B11+D11 -> 592 | H11: =C11+E11 -> 0
A12: Eis | B12: =(B47+D47)*4*B55 -> 570 | D12: =(B48+D48)*3*B55 -> 175.5 | G12: =B12+D12 -> 745.5 | H12: =C12+E12 -> 0 | I12: Camp 1 hat 4 Eispausen, am Freitag kommt der Eiswagen!
A13: Eis-Oma | B13: 400 | G13: =B13+D13 -> 400 | H13: =C13+E13 -> 0
A14: Frühstück | B14: 150 | G14: =B14+D14 -> 150 | H14: =C14+E14 -> 0
A15: Divers | B15: 150 | G15: =B15+D15 -> 150 | H15: =C15+E15 -> 0
A16: Eveeno | B16: 200 | G16: =B16+D16 -> 200 | I16: Anmelde-Plattform
A18: Summe | B18: =SUM(B5:B17) -> 10112 | C18: =SUM(C5:C17) -> 0 | D18: =SUM(D5:D17) -> 3449.74 | E18: =SUM(E5:E17) -> 0 | G18: =SUM(G5:G17) -> 13561.74 | H18: =SUM(H5:H17) -> 0
A20: EINNAHMEN
A21: Position | B21: Preis | C21: Anzahl geplant | D21: Betrag geplant | G21: Betrag real
A22: Camp 1 | B22: 130 | D22: =B47*B22 -> 9750
A23: Camp 2 | B23: 115 | D23: =B48*B23 -> 4025
A24: Getränke- und Eisverkauf Do | D24: 300
A25: Summe | D25: =SUM(D22:D24) -> 14075 | G25: =SUM(G22:G24) -> 0
A27: BELEGE / QUITTUNGEN
A28: Nr. | B28: Datum | C28: Anbieter | D28: Kategorie | E28: Betrag
A29: 1
A30: 2
A31: 3
A32: 4
A33: 5
A34: 6
A36: Summe | E36: =SUM(E29:E35) -> 0
A38: ZUSAMMENFASSUNG
B39: geplant | C39: real
A40: Einnahmen | B40: =D25 -> 14075 | C40: =G25 -> 0
A41: Ausgaben | B41: =B18+D18 -> 13561.74 | C41: =C18+E18 -> 0
A42: Differenz | B42: =B40-B41 -> 513.26 | C42: =C40-C41 -> 0
A45: TEILNEHMER & TRAINER
B46: Teilnehmer geplant | C46: Teilnehmer real | D46: Trainer geplant | E46: Trainer real
A47: Camp 1 | B47: 75 | D47: 20
A48: Camp 2 | B48: 35 | D48: 4
...

Sheet Zeitplan
A1: HOCKEYCAMP
A2: UHRZEIT | B2: Montag | C2: Dienstag | D2: Mittwoch | E2: Donnerstag | F2: Freitag
A3: 8:30 - 9:00 | B3: Ankunft und Ausgabe T-Shirts | C3: Ankunft | D3: Ankunft | E3: Ankunft | F3: Ankunft
A4: 9:00 - 9:30 | B4: Training | C4: Training | D4: Training | E4: Training | F4: Training
A5: 9:30 - 10:00
A6: 10:00 - 10:30
A7: 10:30 -11:00
A8: 11:00 - 11:30 | B8: Obstpause | C8: Obstpause | D8: Obstpause | E8: Obstpause | F8: Obstpause
A9: 11:30 -12:00 | B9: Training | C9: Training | D9: Training | E9: Training | F9: Training
A10: 12:00 - 12:30
A11: 12:30 -13:00
A12: 13:00 - 13:30 | B12: Mittagessen und -pause | C12: Mittagessen und -pause | D12: Mittagessen und -pause | E12: Mittagessen und -pause | F12: Mittagessen und -pause
A13: 13:30 - 14:00
A14: 14:00 - 14:30 | B14: Training | C14: Training | D14: Training | E14: Training | F14: Spielzeit
A15: 14.30 - 15:00
A16: 15:00 - 15:30 | B16: Eispause | C16: Eispause | D16: Eispause | E16: Eispause | F16: Eispause
A17: 15:30 - 16:00 | B17: Training | C17: Training | D17: Training | E17: Spielzeit
A18: 16:00 - 16:30 | F18: Abholung
A19: 16:30 - 17:00 | B19: Abholung | C19: Abholung | D19: Abholung | E19: Grillen + Übernachtung

Sheet Trainer
B2: Name, Vorname | C2: Mo | D2: Di | E2: Mi | F2: Do | G2: Fr | H2: Bonus | I2: Std insg. | J2: Qualifikation | K2: €/Stunde | L2: Auszahlungsbetrag
A3: 1 | J3: Sportl. Leitung | K3: =IF(J3=Daten!A10, Daten!B10, IF(J3=Daten!A11, Daten!B11, IF(J3=Daten!A12, Daten!B12, IF(J3=Daten!A13, Daten!B13)))) -> 10 | L3: =K3*I3 -> 0
A4: 2 | J4: Sportl. Leitung | K4: =IF(J4=Daten!A10, Daten!B10, IF(J4=Daten!A11, Daten!B11, IF(J4=Daten!A12, Daten!B12, IF(J4=Daten!A13, Daten!B13)))) -> 10 | L4: =K4*I4 -> 0
A5: 3 | J5: SportAss | K5: =IF(J5=Daten!A10, Daten!B10, IF(J5=Daten!A11, Daten!B11, IF(J5=Daten!A12, Daten!B12, IF(J5=Daten!A13, Daten!B13)))) -> 7 | L5: =K5*I5 -> 0
A6: 4 | J6: SportAss | K6: =IF(J6=Daten!A10, Daten!B10, IF(J6=Daten!A11, Daten!B11, IF(J6=Daten!A12, Daten!B12, IF(J6=Daten!A13, Daten!B13)))) -> 7 | L6: =K6*I6 -> 0
A7: 5 | J7: SportAss | K7: =IF(J7=Daten!A10, Daten!B10, IF(J7=Daten!A11, Daten!B11, IF(J7=Daten!A12, Daten!B12, IF(J7=Daten!A13, Daten!B13)))) -> 7 | L7: =K7*I7 -> 0
A8: 6 | J8: SportAss | K8: =IF(J8=Daten!A10, Daten!B10, IF(J8=Daten!A11, Daten!B11, IF(J8=Daten!A12, Daten!B12, IF(J8=Daten!A13, Daten!B13)))) -> 7 | L8: =K8*I8 -> 0
A9: 7 | J9: SportAss | K9: =IF(J9=Daten!A10, Daten!B10, IF(J9=Daten!A11, Daten!B11, IF(J9=Daten!A12, Daten!B12, IF(J9=Daten!A13, Daten!B13)))) -> 7 | L9: =K9*I9 -> 0
A10: 8 | J10: ohne Ausbildung | K10: =IF(J10=Daten!A10, Daten!B10, IF(J10=Daten!A11, Daten!B11, IF(J10=Daten!A12, Daten!B12, IF(J10=Daten!A13, Daten!B13)))) -> 5 | L10: =K10*I10 -> 0
A11: 9 | J11: ohne Ausbildung | K11: =IF(J11=Daten!A10, Daten!B10, IF(J11=Daten!A11, Daten!B11, IF(J11=Daten!A12, Daten!B12, IF(J11=Daten!A13, Daten!B13)))) -> 5 | L11: =K11*I11 -> 0
A12: 10 | J12: ohne Ausbildung | K12: =IF(J12=Daten!A10, Daten!B10, IF(J12=Daten!A11, Daten!B11, IF(J12=Daten!A12, Daten!B12, IF(J12=Daten!A13, Daten!B13)))) -> 5 | L12: =K12*I12 -> 0
A13: 11 | J13: ohne Ausbildung | K13: =IF(J13=Daten!A10, Daten!B10, IF(J13=Daten!A11, Daten!B11, IF(J13=Daten!A12, Daten!B12, IF(J13=Daten!A13, Daten!B13)))) -> 5 | L13: =K13*I13 -> 0
A14: 12 | J14: C-Trainer | K14: =IF(J14=Daten!A10, Daten!B10, IF(J14=Daten!A11, Daten!B11, IF(J14=Daten!A12, Daten!B12, IF(J14=Daten!A13, Daten!B13)))) -> 8 | L14: =K14*I14 -> 0
A15: 13 | J15: ohne Ausbildung | K15: =IF(J15=Daten!A10, Daten!B10, IF(J15=Daten!A11, Daten!B11, IF(J15=Daten!A12, Daten!B12, IF(J15=Daten!A13, Daten!B13)))) -> 5 | L15: =K15*I15 -> 0
A16: 14 | J16: ohne Ausbildung | K16: =IF(J16=Daten!A10, Daten!B10, IF(J16=Daten!A11, Daten!B11, IF(J16=Daten!A12, Daten!B12, IF(J16=Daten!A13, Daten!B13)))) -> 5 | L16: =K16*I16 -> 0
A17: 15 | J17: SportAss | K17: =IF(J17=Daten!A10, Daten!B10, IF(J17=Daten!A11, Daten!B11, IF(J17=Daten!A12, Daten!B12, IF(J17=Daten!A13, Daten!B13)))) -> 7 | L17: =K17*I17 -> 0
A18: 16 | J18: SportAss | K18: =IF(J18=Daten!A10, Daten!B10, IF(J18=Daten!A11, Daten!B11, IF(J18=Daten!A12, Daten!B12, IF(J18=Daten!A13, Daten!B13)))) -> 7 | L18: =K18*I18 -> 0
A19: 17 | J19: ohne Ausbildung | K19: =IF(J19=Daten!A10, Daten!B10, IF(J19=Daten!A11, Daten!B11, IF(J19=Daten!A12, Daten!B12, IF(J19=Daten!A13, Daten!B13)))) -> 5 | L19: =K19*I19 -> 0
A20: 18 | J20: C-Trainer | K20: =IF(J20=Daten!A10, Daten!B10, IF(J20=Daten!A11, Daten!B11, IF(J20=Daten!A12, Daten!B12, IF(J20=Daten!A13, Daten!B13)))) -> 8 | L20: =K20*I20 -> 0
A21: 19 | J21: SportAss | K21: =IF(J21=Daten!A10, Daten!B10, IF(J21=Daten!A11, Daten!B11, IF(J21=Daten!A12, Daten!B12, IF(J21=Daten!A13, Daten!B13)))) -> 7 | L21: =K21*I21 -> 0
A22: 20 | J22: SportAss | K22: =IF(J22=Daten!A10, Daten!B10, IF(J22=Daten!A11, Daten!B11, IF(J22=Daten!A12, Daten!B12, IF(J22=Daten!A13, Daten!B13)))) -> 7 | L22: =K22*I22 -> 0
A23: 21 | J23: ohne Ausbildung | K23: =IF(J23=Daten!A10, Daten!B10, IF(J23=Daten!A11, Daten!B11, IF(J23=Daten!A12, Daten!B12, IF(J23=Daten!A13, Daten!B13)))) -> 5 | L23: =K23*I23 -> 0
A24: 22 | J24: ohne Ausbildung | K24: =IF(J24=Daten!A10, Daten!B10, IF(J24=Daten!A11, Daten!B11, IF(J24=Daten!A12, Daten!B12, IF(J24=Daten!A13, Daten!B13)))) -> 5 | L24: =K24*I24 -> 0
A25: 23 | J25: ohne Ausbildung | K25: =IF(J25=Daten!A10, Daten!B10, IF(J25=Daten!A11, Daten!B11, IF(J25=Daten!A12, Daten!B12, IF(J25=Daten!A13, Daten!B13)))) -> 5 | L25: =K25*I25 -> 0
I26: =SUM(I3:I25) -> 0 | K26: Gesamt: | L26: =SUM(L3:L25) -> 0

Sheet Daten
A1: U-Einteilung
A2: U6
A3: U8
A4: U10
A5: U12
A6: U14
A7: U16
A9: Trainervergütung
A10: ohne Ausbildung | B10: 5
A11: SportAss | B11: 7
A12: C-Trainer | B12: 8
A13: Sportl. Leitung | B13: 10
